nohup: ignoring input
2024-12-10 18:16:46 - INFO - PMTfication starts...
2024-12-10 18:16:46 - INFO - The number of files in the subdirectory: 2
2024-12-10 18:16:46 - INFO - The number of files in the subdirectory: 2
2024-12-10 18:16:46 - INFO - Using up to 1 workers.
2024-12-10 18:16:46 - INFO - PMTfying Snowstorm...
2024-12-10 18:16:46 - INFO - Found 2 database files in subdirectory 99999.
Processing 99999:   0%|          | 0/2 [00:00<?, ?it/s]2024-12-10 18:16:46 - INFO - Processing shard 1 of part 98 in subdirectory 99999.
2024-12-10 18:16:47 - ERROR - Error processing file merged_part_98.db: _get_truth_pa_shard() missing 1 required positional argument: 'event_no_subset'
concurrent.futures.process._RemoteTraceback: 
"""
Traceback (most recent call last):
  File "/usr/lib64/python3.9/concurrent/futures/process.py", line 246, in _process_worker
    r = call_item.fn(*call_item.args, **call_item.kwargs)
  File "/lustre/hpc/icecube/cyan/factory/DOMification/PMTfier.py", line 209, in pmtfy_part
    consolidated_truth = self._divide_and_conquer_part(
  File "/lustre/hpc/icecube/cyan/factory/DOMification/PMTfier.py", line 191, in _divide_and_conquer_part
    pa_truth_shard = self.pmtfy_shard(
  File "/lustre/hpc/icecube/cyan/factory/DOMification/PMTfier.py", line 178, in pmtfy_shard
    pa_truth_shard = truth_maker(int(self.subdir_tag), part_no, shard_no, event_batch)
  File "/lustre/hpc/icecube/cyan/factory/DOMification/PMT_truth_maker.py", line 47, in __call__
    truth_table = self._get_truth_pa_shard(receipt_pa)
TypeError: _get_truth_pa_shard() missing 1 required positional argument: 'event_no_subset'
"""

The above exception was the direct cause of the following exception:

Traceback (most recent call last):
  File "/lustre/hpc/icecube/cyan/factory/DOMification/PMTfier.py", line 241, in pmtfy_subdir_parallel
    future.result()
  File "/usr/lib64/python3.9/concurrent/futures/_base.py", line 439, in result
    return self.__get_result()
  File "/usr/lib64/python3.9/concurrent/futures/_base.py", line 391, in __get_result
    raise self._exception
TypeError: _get_truth_pa_shard() missing 1 required positional argument: 'event_no_subset'
Processing 99999:  50%|█████     | 1/2 [00:01<00:01,  1.40s/it]2024-12-10 18:16:47 - INFO - Processing shard 1 of part 99 in subdirectory 99999.
2024-12-10 18:16:50 - ERROR - Error processing file merged_part_99.db: _get_truth_pa_shard() missing 1 required positional argument: 'event_no_subset'
concurrent.futures.process._RemoteTraceback: 
"""
Traceback (most recent call last):
  File "/usr/lib64/python3.9/concurrent/futures/process.py", line 246, in _process_worker
    r = call_item.fn(*call_item.args, **call_item.kwargs)
  File "/lustre/hpc/icecube/cyan/factory/DOMification/PMTfier.py", line 209, in pmtfy_part
    consolidated_truth = self._divide_and_conquer_part(
  File "/lustre/hpc/icecube/cyan/factory/DOMification/PMTfier.py", line 191, in _divide_and_conquer_part
    pa_truth_shard = self.pmtfy_shard(
  File "/lustre/hpc/icecube/cyan/factory/DOMification/PMTfier.py", line 178, in pmtfy_shard
    pa_truth_shard = truth_maker(int(self.subdir_tag), part_no, shard_no, event_batch)
  File "/lustre/hpc/icecube/cyan/factory/DOMification/PMT_truth_maker.py", line 47, in __call__
    truth_table = self._get_truth_pa_shard(receipt_pa)
TypeError: _get_truth_pa_shard() missing 1 required positional argument: 'event_no_subset'
"""

The above exception was the direct cause of the following exception:

Traceback (most recent call last):
  File "/lustre/hpc/icecube/cyan/factory/DOMification/PMTfier.py", line 241, in pmtfy_subdir_parallel
    future.result()
  File "/usr/lib64/python3.9/concurrent/futures/_base.py", line 439, in result
    return self.__get_result()
  File "/usr/lib64/python3.9/concurrent/futures/_base.py", line 391, in __get_result
    raise self._exception
TypeError: _get_truth_pa_shard() missing 1 required positional argument: 'event_no_subset'
Processing 99999: 100%|██████████| 2/2 [00:04<00:00,  2.61s/it]Processing 99999: 100%|██████████| 2/2 [00:04<00:00,  2.43s/it]
2024-12-10 18:16:50 - INFO - PMTfication for Snowstorm completed.
2024-12-10 18:16:50 - INFO - PMTfying Corsika...
2024-12-10 18:16:50 - INFO - Found 2 database files in subdirectory 9999999-9999999.
Processing 9999999-9999999:   0%|          | 0/2 [00:00<?, ?it/s]2024-12-10 18:16:51 - INFO - Processing shard 1 of part 96 in subdirectory 9999999-9999999.
2024-12-10 18:16:53 - ERROR - Error processing file merged_part_96.db: _get_truth_pa_shard() missing 1 required positional argument: 'event_no_subset'
concurrent.futures.process._RemoteTraceback: 
"""
Traceback (most recent call last):
  File "/usr/lib64/python3.9/concurrent/futures/process.py", line 246, in _process_worker
    r = call_item.fn(*call_item.args, **call_item.kwargs)
  File "/lustre/hpc/icecube/cyan/factory/DOMification/PMTfier.py", line 209, in pmtfy_part
    consolidated_truth = self._divide_and_conquer_part(
  File "/lustre/hpc/icecube/cyan/factory/DOMification/PMTfier.py", line 191, in _divide_and_conquer_part
    pa_truth_shard = self.pmtfy_shard(
  File "/lustre/hpc/icecube/cyan/factory/DOMification/PMTfier.py", line 178, in pmtfy_shard
    pa_truth_shard = truth_maker(int(self.subdir_tag), part_no, shard_no, event_batch)
  File "/lustre/hpc/icecube/cyan/factory/DOMification/PMT_truth_maker.py", line 47, in __call__
    truth_table = self._get_truth_pa_shard(receipt_pa)
TypeError: _get_truth_pa_shard() missing 1 required positional argument: 'event_no_subset'
"""

The above exception was the direct cause of the following exception:

Traceback (most recent call last):
  File "/lustre/hpc/icecube/cyan/factory/DOMification/PMTfier.py", line 241, in pmtfy_subdir_parallel
    future.result()
  File "/usr/lib64/python3.9/concurrent/futures/_base.py", line 439, in result
    return self.__get_result()
  File "/usr/lib64/python3.9/concurrent/futures/_base.py", line 391, in __get_result
    raise self._exception
TypeError: _get_truth_pa_shard() missing 1 required positional argument: 'event_no_subset'
Processing 9999999-9999999:  50%|█████     | 1/2 [00:02<00:02,  2.43s/it]2024-12-10 18:16:53 - INFO - Processing shard 1 of part 97 in subdirectory 9999999-9999999.
2024-12-10 18:16:56 - ERROR - Error processing file merged_part_97.db: _get_truth_pa_shard() missing 1 required positional argument: 'event_no_subset'
concurrent.futures.process._RemoteTraceback: 
"""
Traceback (most recent call last):
  File "/usr/lib64/python3.9/concurrent/futures/process.py", line 246, in _process_worker
    r = call_item.fn(*call_item.args, **call_item.kwargs)
  File "/lustre/hpc/icecube/cyan/factory/DOMification/PMTfier.py", line 209, in pmtfy_part
    consolidated_truth = self._divide_and_conquer_part(
  File "/lustre/hpc/icecube/cyan/factory/DOMification/PMTfier.py", line 191, in _divide_and_conquer_part
    pa_truth_shard = self.pmtfy_shard(
  File "/lustre/hpc/icecube/cyan/factory/DOMification/PMTfier.py", line 178, in pmtfy_shard
    pa_truth_shard = truth_maker(int(self.subdir_tag), part_no, shard_no, event_batch)
  File "/lustre/hpc/icecube/cyan/factory/DOMification/PMT_truth_maker.py", line 47, in __call__
    truth_table = self._get_truth_pa_shard(receipt_pa)
TypeError: _get_truth_pa_shard() missing 1 required positional argument: 'event_no_subset'
"""

The above exception was the direct cause of the following exception:

Traceback (most recent call last):
  File "/lustre/hpc/icecube/cyan/factory/DOMification/PMTfier.py", line 241, in pmtfy_subdir_parallel
    future.result()
  File "/usr/lib64/python3.9/concurrent/futures/_base.py", line 439, in result
    return self.__get_result()
  File "/usr/lib64/python3.9/concurrent/futures/_base.py", line 391, in __get_result
    raise self._exception
TypeError: _get_truth_pa_shard() missing 1 required positional argument: 'event_no_subset'
Processing 9999999-9999999: 100%|██████████| 2/2 [00:05<00:00,  2.65s/it]Processing 9999999-9999999: 100%|██████████| 2/2 [00:05<00:00,  2.62s/it]
2024-12-10 18:16:56 - INFO - PMTfication for Corsika completed.
2024-12-10 18:16:56 - INFO - PMTfication completed.
