nohup: ignoring input
2024-11-22 10:56:41 - INFO - PMTfication starts...
2024-11-22 10:56:41 - INFO - The number of files in the subdirectory: 2
2024-11-22 10:56:41 - INFO - Using up to 1 workers.
2024-11-22 10:56:41 - INFO - Found 2 database files in subdirectory 99999.
Processing 99999:   0%|          | 0/2 [00:00<?, ?it/s]2024-11-22 10:56:41 - ERROR - Error processing file merged_part_98.db: pmtfy_shard() missing 1 required positional argument: 'event_batch'
concurrent.futures.process._RemoteTraceback: 
"""
Traceback (most recent call last):
  File "/usr/lib64/python3.9/concurrent/futures/process.py", line 246, in _process_worker
    r = call_item.fn(*call_item.args, **call_item.kwargs)
  File "/lustre/hpc/icecube/cyan/factory/DOMification/PMTfier.py", line 197, in pmtfy_part
    consolidated_truth = self._divide_and_conquer_part(
  File "/lustre/hpc/icecube/cyan/factory/DOMification/PMTfier.py", line 176, in _divide_and_conquer_part
    pa_truth_shard = self.pmtfy_shard(
TypeError: pmtfy_shard() missing 1 required positional argument: 'event_batch'
"""

The above exception was the direct cause of the following exception:

Traceback (most recent call last):
  File "/lustre/hpc/icecube/cyan/factory/DOMification/PMTfier.py", line 245, in pmtfy_subdir_parallel
    future.result()
  File "/usr/lib64/python3.9/concurrent/futures/_base.py", line 439, in result
    return self.__get_result()
  File "/usr/lib64/python3.9/concurrent/futures/_base.py", line 391, in __get_result
    raise self._exception
TypeError: pmtfy_shard() missing 1 required positional argument: 'event_batch'
Processing 99999:  50%|█████     | 1/2 [00:00<00:00,  6.31it/s]2024-11-22 10:56:41 - ERROR - Error processing file merged_part_99.db: pmtfy_shard() missing 1 required positional argument: 'event_batch'
concurrent.futures.process._RemoteTraceback: 
"""
Traceback (most recent call last):
  File "/usr/lib64/python3.9/concurrent/futures/process.py", line 246, in _process_worker
    r = call_item.fn(*call_item.args, **call_item.kwargs)
  File "/lustre/hpc/icecube/cyan/factory/DOMification/PMTfier.py", line 197, in pmtfy_part
    consolidated_truth = self._divide_and_conquer_part(
  File "/lustre/hpc/icecube/cyan/factory/DOMification/PMTfier.py", line 176, in _divide_and_conquer_part
    pa_truth_shard = self.pmtfy_shard(
TypeError: pmtfy_shard() missing 1 required positional argument: 'event_batch'
"""

The above exception was the direct cause of the following exception:

Traceback (most recent call last):
  File "/lustre/hpc/icecube/cyan/factory/DOMification/PMTfier.py", line 245, in pmtfy_subdir_parallel
    future.result()
  File "/usr/lib64/python3.9/concurrent/futures/_base.py", line 439, in result
    return self.__get_result()
  File "/usr/lib64/python3.9/concurrent/futures/_base.py", line 391, in __get_result
    raise self._exception
TypeError: pmtfy_shard() missing 1 required positional argument: 'event_batch'
Processing 99999: 100%|██████████| 2/2 [00:00<00:00,  5.91it/s]Processing 99999: 100%|██████████| 2/2 [00:00<00:00,  5.96it/s]
2024-11-22 10:56:41 - INFO - PMTfication completed.
