nohup: ignoring input
2024-12-11 10:59:15 - INFO - PMTfication starts...
2024-12-11 10:59:15 - INFO - The number of files in the subdirectory: 2
2024-12-11 10:59:15 - INFO - The number of files in the subdirectory: 2
2024-12-11 10:59:15 - INFO - Using up to 1 workers.
2024-12-11 10:59:15 - INFO - PMTfying Snowstorm...
2024-12-11 10:59:15 - INFO - Found 2 database files in subdirectory 99999.
Processing 99999:   0%|          | 0/2 [00:00<?, ?it/s]2024-12-11 10:59:15 - INFO - Processing shard 1 of part 98 in subdirectory 99999.
2024-12-11 10:59:18 - ERROR - Error processing file merged_part_98.db: "The passed mapping doesn't contain the following field(s) of the schema: HE_daughter_event_no"
concurrent.futures.process._RemoteTraceback: 
"""
Traceback (most recent call last):
  File "pyarrow/table.pxi", line 6291, in pyarrow.lib._from_pydict
KeyError: 'HE_daughter_event_no'

During handling of the above exception, another exception occurred:

Traceback (most recent call last):
  File "pyarrow/table.pxi", line 6294, in pyarrow.lib._from_pydict
KeyError: b'HE_daughter_event_no'

During handling of the above exception, another exception occurred:

Traceback (most recent call last):
  File "/usr/lib64/python3.9/concurrent/futures/process.py", line 246, in _process_worker
    r = call_item.fn(*call_item.args, **call_item.kwargs)
  File "/lustre/hpc/icecube/cyan/factory/DOMification/PMTfier.py", line 207, in pmtfy_part
    consolidated_truth = self._divide_and_conquer_part(
  File "/lustre/hpc/icecube/cyan/factory/DOMification/PMTfier.py", line 189, in _divide_and_conquer_part
    pa_truth_shard = self.pmtfy_shard(
  File "/lustre/hpc/icecube/cyan/factory/DOMification/PMTfier.py", line 176, in pmtfy_shard
    pa_truth_shard = truth_maker(int(self.subdir_tag), part_no, shard_no, event_batch)
  File "/lustre/hpc/icecube/cyan/factory/DOMification/PMT_truth_maker.py", line 58, in __call__
    return self._merge_tables(truth_table, HE_daughter_table, subdirectory_no, part_no, shard_no)
  File "/lustre/hpc/icecube/cyan/factory/DOMification/PMT_truth_maker.py", line 118, in _merge_tables
    return pa.Table.from_pydict(merged_data, schema=PMTTruthMaker._MERGED_SCHEMA)
  File "pyarrow/table.pxi", line 1968, in pyarrow.lib._Tabular.from_pydict
  File "pyarrow/table.pxi", line 6298, in pyarrow.lib._from_pydict
KeyError: "The passed mapping doesn't contain the following field(s) of the schema: HE_daughter_event_no"
"""

The above exception was the direct cause of the following exception:

Traceback (most recent call last):
  File "/lustre/hpc/icecube/cyan/factory/DOMification/PMTfier.py", line 239, in pmtfy_subdir_parallel
    future.result()
  File "/usr/lib64/python3.9/concurrent/futures/_base.py", line 439, in result
    return self.__get_result()
  File "/usr/lib64/python3.9/concurrent/futures/_base.py", line 391, in __get_result
    raise self._exception
KeyError: "The passed mapping doesn't contain the following field(s) of the schema: HE_daughter_event_no"
Processing 99999:  50%|█████     | 1/2 [00:02<00:02,  2.96s/it]2024-12-11 10:59:18 - INFO - Processing shard 1 of part 99 in subdirectory 99999.
2024-12-11 10:59:24 - ERROR - Error processing file merged_part_99.db: "The passed mapping doesn't contain the following field(s) of the schema: HE_daughter_event_no"
concurrent.futures.process._RemoteTraceback: 
"""
Traceback (most recent call last):
  File "pyarrow/table.pxi", line 6291, in pyarrow.lib._from_pydict
KeyError: 'HE_daughter_event_no'

During handling of the above exception, another exception occurred:

Traceback (most recent call last):
  File "pyarrow/table.pxi", line 6294, in pyarrow.lib._from_pydict
KeyError: b'HE_daughter_event_no'

During handling of the above exception, another exception occurred:

Traceback (most recent call last):
  File "/usr/lib64/python3.9/concurrent/futures/process.py", line 246, in _process_worker
    r = call_item.fn(*call_item.args, **call_item.kwargs)
  File "/lustre/hpc/icecube/cyan/factory/DOMification/PMTfier.py", line 207, in pmtfy_part
    consolidated_truth = self._divide_and_conquer_part(
  File "/lustre/hpc/icecube/cyan/factory/DOMification/PMTfier.py", line 189, in _divide_and_conquer_part
    pa_truth_shard = self.pmtfy_shard(
  File "/lustre/hpc/icecube/cyan/factory/DOMification/PMTfier.py", line 176, in pmtfy_shard
    pa_truth_shard = truth_maker(int(self.subdir_tag), part_no, shard_no, event_batch)
  File "/lustre/hpc/icecube/cyan/factory/DOMification/PMT_truth_maker.py", line 58, in __call__
    return self._merge_tables(truth_table, HE_daughter_table, subdirectory_no, part_no, shard_no)
  File "/lustre/hpc/icecube/cyan/factory/DOMification/PMT_truth_maker.py", line 118, in _merge_tables
    return pa.Table.from_pydict(merged_data, schema=PMTTruthMaker._MERGED_SCHEMA)
  File "pyarrow/table.pxi", line 1968, in pyarrow.lib._Tabular.from_pydict
  File "pyarrow/table.pxi", line 6298, in pyarrow.lib._from_pydict
KeyError: "The passed mapping doesn't contain the following field(s) of the schema: HE_daughter_event_no"
"""

The above exception was the direct cause of the following exception:

Traceback (most recent call last):
  File "/lustre/hpc/icecube/cyan/factory/DOMification/PMTfier.py", line 239, in pmtfy_subdir_parallel
    future.result()
  File "/usr/lib64/python3.9/concurrent/futures/_base.py", line 439, in result
    return self.__get_result()
  File "/usr/lib64/python3.9/concurrent/futures/_base.py", line 391, in __get_result
    raise self._exception
KeyError: "The passed mapping doesn't contain the following field(s) of the schema: HE_daughter_event_no"
Processing 99999: 100%|██████████| 2/2 [00:08<00:00,  4.28s/it]Processing 99999: 100%|██████████| 2/2 [00:08<00:00,  4.08s/it]
2024-12-11 10:59:24 - INFO - PMTfication for Snowstorm completed.
2024-12-11 10:59:24 - INFO - PMTfying Corsika...
2024-12-11 10:59:24 - INFO - Found 2 database files in subdirectory 9999999-9999999.
Processing 9999999-9999999:   0%|          | 0/2 [00:00<?, ?it/s]2024-12-11 10:59:24 - INFO - Processing shard 1 of part 96 in subdirectory 9999999-9999999.
2024-12-11 10:59:27 - ERROR - Error processing file merged_part_96.db: "The passed mapping doesn't contain the following field(s) of the schema: HE_daughter_event_no"
concurrent.futures.process._RemoteTraceback: 
"""
Traceback (most recent call last):
  File "pyarrow/table.pxi", line 6291, in pyarrow.lib._from_pydict
KeyError: 'HE_daughter_event_no'

During handling of the above exception, another exception occurred:

Traceback (most recent call last):
  File "pyarrow/table.pxi", line 6294, in pyarrow.lib._from_pydict
KeyError: b'HE_daughter_event_no'

During handling of the above exception, another exception occurred:

Traceback (most recent call last):
  File "/usr/lib64/python3.9/concurrent/futures/process.py", line 246, in _process_worker
    r = call_item.fn(*call_item.args, **call_item.kwargs)
  File "/lustre/hpc/icecube/cyan/factory/DOMification/PMTfier.py", line 207, in pmtfy_part
    consolidated_truth = self._divide_and_conquer_part(
  File "/lustre/hpc/icecube/cyan/factory/DOMification/PMTfier.py", line 189, in _divide_and_conquer_part
    pa_truth_shard = self.pmtfy_shard(
  File "/lustre/hpc/icecube/cyan/factory/DOMification/PMTfier.py", line 176, in pmtfy_shard
    pa_truth_shard = truth_maker(int(self.subdir_tag), part_no, shard_no, event_batch)
  File "/lustre/hpc/icecube/cyan/factory/DOMification/PMT_truth_maker.py", line 58, in __call__
    return self._merge_tables(truth_table, HE_daughter_table, subdirectory_no, part_no, shard_no)
  File "/lustre/hpc/icecube/cyan/factory/DOMification/PMT_truth_maker.py", line 118, in _merge_tables
    return pa.Table.from_pydict(merged_data, schema=PMTTruthMaker._MERGED_SCHEMA)
  File "pyarrow/table.pxi", line 1968, in pyarrow.lib._Tabular.from_pydict
  File "pyarrow/table.pxi", line 6298, in pyarrow.lib._from_pydict
KeyError: "The passed mapping doesn't contain the following field(s) of the schema: HE_daughter_event_no"
"""

The above exception was the direct cause of the following exception:

Traceback (most recent call last):
  File "/lustre/hpc/icecube/cyan/factory/DOMification/PMTfier.py", line 239, in pmtfy_subdir_parallel
    future.result()
  File "/usr/lib64/python3.9/concurrent/futures/_base.py", line 439, in result
    return self.__get_result()
  File "/usr/lib64/python3.9/concurrent/futures/_base.py", line 391, in __get_result
    raise self._exception
KeyError: "The passed mapping doesn't contain the following field(s) of the schema: HE_daughter_event_no"
Processing 9999999-9999999:  50%|█████     | 1/2 [00:03<00:03,  3.25s/it]2024-12-11 10:59:27 - INFO - Processing shard 1 of part 97 in subdirectory 9999999-9999999.
2024-12-11 10:59:30 - ERROR - Error processing file merged_part_97.db: "The passed mapping doesn't contain the following field(s) of the schema: HE_daughter_event_no"
concurrent.futures.process._RemoteTraceback: 
"""
Traceback (most recent call last):
  File "pyarrow/table.pxi", line 6291, in pyarrow.lib._from_pydict
KeyError: 'HE_daughter_event_no'

During handling of the above exception, another exception occurred:

Traceback (most recent call last):
  File "pyarrow/table.pxi", line 6294, in pyarrow.lib._from_pydict
KeyError: b'HE_daughter_event_no'

During handling of the above exception, another exception occurred:

Traceback (most recent call last):
  File "/usr/lib64/python3.9/concurrent/futures/process.py", line 246, in _process_worker
    r = call_item.fn(*call_item.args, **call_item.kwargs)
  File "/lustre/hpc/icecube/cyan/factory/DOMification/PMTfier.py", line 207, in pmtfy_part
    consolidated_truth = self._divide_and_conquer_part(
  File "/lustre/hpc/icecube/cyan/factory/DOMification/PMTfier.py", line 189, in _divide_and_conquer_part
    pa_truth_shard = self.pmtfy_shard(
  File "/lustre/hpc/icecube/cyan/factory/DOMification/PMTfier.py", line 176, in pmtfy_shard
    pa_truth_shard = truth_maker(int(self.subdir_tag), part_no, shard_no, event_batch)
  File "/lustre/hpc/icecube/cyan/factory/DOMification/PMT_truth_maker.py", line 58, in __call__
    return self._merge_tables(truth_table, HE_daughter_table, subdirectory_no, part_no, shard_no)
  File "/lustre/hpc/icecube/cyan/factory/DOMification/PMT_truth_maker.py", line 118, in _merge_tables
    return pa.Table.from_pydict(merged_data, schema=PMTTruthMaker._MERGED_SCHEMA)
  File "pyarrow/table.pxi", line 1968, in pyarrow.lib._Tabular.from_pydict
  File "pyarrow/table.pxi", line 6298, in pyarrow.lib._from_pydict
KeyError: "The passed mapping doesn't contain the following field(s) of the schema: HE_daughter_event_no"
"""

The above exception was the direct cause of the following exception:

Traceback (most recent call last):
  File "/lustre/hpc/icecube/cyan/factory/DOMification/PMTfier.py", line 239, in pmtfy_subdir_parallel
    future.result()
  File "/usr/lib64/python3.9/concurrent/futures/_base.py", line 439, in result
    return self.__get_result()
  File "/usr/lib64/python3.9/concurrent/futures/_base.py", line 391, in __get_result
    raise self._exception
KeyError: "The passed mapping doesn't contain the following field(s) of the schema: HE_daughter_event_no"
Processing 9999999-9999999: 100%|██████████| 2/2 [00:06<00:00,  3.28s/it]Processing 9999999-9999999: 100%|██████████| 2/2 [00:06<00:00,  3.27s/it]
2024-12-11 10:59:30 - INFO - PMTfication for Corsika completed.
2024-12-11 10:59:30 - INFO - PMTfication completed.
