nohup: ignoring input
2024-12-10 18:10:16 - INFO - PMTfication starts...
2024-12-10 18:10:16 - INFO - The number of files in the subdirectory: 2
2024-12-10 18:10:16 - INFO - The number of files in the subdirectory: 2
2024-12-10 18:10:16 - INFO - Using up to 1 workers.
2024-12-10 18:10:16 - INFO - PMTfying Snowstorm...
2024-12-10 18:10:16 - INFO - Found 2 database files in subdirectory 99999.
Processing 99999:   0%|          | 0/2 [00:00<?, ?it/s]2024-12-10 18:10:16 - INFO - Processing shard 1 of part 98 in subdirectory 99999.
2024-12-10 18:10:18 - ERROR - Error processing file merged_part_98.db: _add_enhance_event_no() takes 3 positional arguments but 4 were given
concurrent.futures.process._RemoteTraceback: 
"""
Traceback (most recent call last):
  File "/usr/lib64/python3.9/concurrent/futures/process.py", line 246, in _process_worker
    r = call_item.fn(*call_item.args, **call_item.kwargs)
  File "/lustre/hpc/icecube/cyan/factory/DOMification/PMTfier.py", line 210, in pmtfy_part
    consolidated_truth = self._divide_and_conquer_part(
  File "/lustre/hpc/icecube/cyan/factory/DOMification/PMTfier.py", line 192, in _divide_and_conquer_part
    pa_truth_shard = self.pmtfy_shard(
  File "/lustre/hpc/icecube/cyan/factory/DOMification/PMTfier.py", line 171, in pmtfy_shard
    pa_pmtfied = self._add_enhance_event_no(pa_pmtfied, self.subdir_tag, part_no)
TypeError: _add_enhance_event_no() takes 3 positional arguments but 4 were given
"""

The above exception was the direct cause of the following exception:

Traceback (most recent call last):
  File "/lustre/hpc/icecube/cyan/factory/DOMification/PMTfier.py", line 242, in pmtfy_subdir_parallel
    future.result()
  File "/usr/lib64/python3.9/concurrent/futures/_base.py", line 439, in result
    return self.__get_result()
  File "/usr/lib64/python3.9/concurrent/futures/_base.py", line 391, in __get_result
    raise self._exception
TypeError: _add_enhance_event_no() takes 3 positional arguments but 4 were given
Processing 99999:  50%|█████     | 1/2 [00:01<00:01,  1.45s/it]2024-12-10 18:10:18 - INFO - Processing shard 1 of part 99 in subdirectory 99999.
2024-12-10 18:10:22 - ERROR - Error processing file merged_part_99.db: _add_enhance_event_no() takes 3 positional arguments but 4 were given
concurrent.futures.process._RemoteTraceback: 
"""
Traceback (most recent call last):
  File "/usr/lib64/python3.9/concurrent/futures/process.py", line 246, in _process_worker
    r = call_item.fn(*call_item.args, **call_item.kwargs)
  File "/lustre/hpc/icecube/cyan/factory/DOMification/PMTfier.py", line 210, in pmtfy_part
    consolidated_truth = self._divide_and_conquer_part(
  File "/lustre/hpc/icecube/cyan/factory/DOMification/PMTfier.py", line 192, in _divide_and_conquer_part
    pa_truth_shard = self.pmtfy_shard(
  File "/lustre/hpc/icecube/cyan/factory/DOMification/PMTfier.py", line 171, in pmtfy_shard
    pa_pmtfied = self._add_enhance_event_no(pa_pmtfied, self.subdir_tag, part_no)
TypeError: _add_enhance_event_no() takes 3 positional arguments but 4 were given
"""

The above exception was the direct cause of the following exception:

Traceback (most recent call last):
  File "/lustre/hpc/icecube/cyan/factory/DOMification/PMTfier.py", line 242, in pmtfy_subdir_parallel
    future.result()
  File "/usr/lib64/python3.9/concurrent/futures/_base.py", line 439, in result
    return self.__get_result()
  File "/usr/lib64/python3.9/concurrent/futures/_base.py", line 391, in __get_result
    raise self._exception
TypeError: _add_enhance_event_no() takes 3 positional arguments but 4 were given
Processing 99999: 100%|██████████| 2/2 [00:05<00:00,  2.94s/it]Processing 99999: 100%|██████████| 2/2 [00:05<00:00,  2.72s/it]
2024-12-10 18:10:22 - INFO - PMTfication for Snowstorm completed.
2024-12-10 18:10:22 - INFO - PMTfying Corsika...
2024-12-10 18:10:22 - INFO - Found 2 database files in subdirectory 9999999-9999999.
Processing 9999999-9999999:   0%|          | 0/2 [00:00<?, ?it/s]2024-12-10 18:10:22 - INFO - Processing shard 1 of part 96 in subdirectory 9999999-9999999.
2024-12-10 18:10:24 - ERROR - Error processing file merged_part_96.db: _add_enhance_event_no() takes 3 positional arguments but 4 were given
concurrent.futures.process._RemoteTraceback: 
"""
Traceback (most recent call last):
  File "/usr/lib64/python3.9/concurrent/futures/process.py", line 246, in _process_worker
    r = call_item.fn(*call_item.args, **call_item.kwargs)
  File "/lustre/hpc/icecube/cyan/factory/DOMification/PMTfier.py", line 210, in pmtfy_part
    consolidated_truth = self._divide_and_conquer_part(
  File "/lustre/hpc/icecube/cyan/factory/DOMification/PMTfier.py", line 192, in _divide_and_conquer_part
    pa_truth_shard = self.pmtfy_shard(
  File "/lustre/hpc/icecube/cyan/factory/DOMification/PMTfier.py", line 171, in pmtfy_shard
    pa_pmtfied = self._add_enhance_event_no(pa_pmtfied, self.subdir_tag, part_no)
TypeError: _add_enhance_event_no() takes 3 positional arguments but 4 were given
"""

The above exception was the direct cause of the following exception:

Traceback (most recent call last):
  File "/lustre/hpc/icecube/cyan/factory/DOMification/PMTfier.py", line 242, in pmtfy_subdir_parallel
    future.result()
  File "/usr/lib64/python3.9/concurrent/futures/_base.py", line 439, in result
    return self.__get_result()
  File "/usr/lib64/python3.9/concurrent/futures/_base.py", line 391, in __get_result
    raise self._exception
TypeError: _add_enhance_event_no() takes 3 positional arguments but 4 were given
Processing 9999999-9999999:  50%|█████     | 1/2 [00:02<00:02,  2.42s/it]2024-12-10 18:10:24 - INFO - Processing shard 1 of part 97 in subdirectory 9999999-9999999.
2024-12-10 18:10:27 - ERROR - Error processing file merged_part_97.db: _add_enhance_event_no() takes 3 positional arguments but 4 were given
concurrent.futures.process._RemoteTraceback: 
"""
Traceback (most recent call last):
  File "/usr/lib64/python3.9/concurrent/futures/process.py", line 246, in _process_worker
    r = call_item.fn(*call_item.args, **call_item.kwargs)
  File "/lustre/hpc/icecube/cyan/factory/DOMification/PMTfier.py", line 210, in pmtfy_part
    consolidated_truth = self._divide_and_conquer_part(
  File "/lustre/hpc/icecube/cyan/factory/DOMification/PMTfier.py", line 192, in _divide_and_conquer_part
    pa_truth_shard = self.pmtfy_shard(
  File "/lustre/hpc/icecube/cyan/factory/DOMification/PMTfier.py", line 171, in pmtfy_shard
    pa_pmtfied = self._add_enhance_event_no(pa_pmtfied, self.subdir_tag, part_no)
TypeError: _add_enhance_event_no() takes 3 positional arguments but 4 were given
"""

The above exception was the direct cause of the following exception:

Traceback (most recent call last):
  File "/lustre/hpc/icecube/cyan/factory/DOMification/PMTfier.py", line 242, in pmtfy_subdir_parallel
    future.result()
  File "/usr/lib64/python3.9/concurrent/futures/_base.py", line 439, in result
    return self.__get_result()
  File "/usr/lib64/python3.9/concurrent/futures/_base.py", line 391, in __get_result
    raise self._exception
TypeError: _add_enhance_event_no() takes 3 positional arguments but 4 were given
Processing 9999999-9999999: 100%|██████████| 2/2 [00:05<00:00,  2.73s/it]Processing 9999999-9999999: 100%|██████████| 2/2 [00:05<00:00,  2.68s/it]
2024-12-10 18:10:27 - INFO - PMTfication for Corsika completed.
2024-12-10 18:10:27 - INFO - PMTfication completed.
