nohup: ignoring input
2024-11-26 14:13:31 - INFO - PMTfication starts...
2024-11-26 14:13:31 - INFO - The number of files in the subdirectory: 2
2024-11-26 14:13:31 - INFO - Using up to 1 workers.
2024-11-26 14:13:31 - INFO - Found 2 database files in subdirectory 99999.
Processing 99999:   0%|          | 0/2 [00:00<?, ?it/s]2024-11-26 14:13:31 - INFO - Processing shard 1 of part 98 in subdirectory 99999.
2024-11-26 14:13:31 - ERROR - Error processing file merged_part_98.db: type object 'PMTSummariser' has no attribute '_SCHEMA'
concurrent.futures.process._RemoteTraceback: 
"""
Traceback (most recent call last):
  File "/usr/lib64/python3.9/concurrent/futures/process.py", line 246, in _process_worker
    r = call_item.fn(*call_item.args, **call_item.kwargs)
  File "/lustre/hpc/icecube/cyan/factory/DOMification/PMTfier.py", line 205, in pmtfy_part
    consolidated_truth = self._divide_and_conquer_part(
  File "/lustre/hpc/icecube/cyan/factory/DOMification/PMTfier.py", line 183, in _divide_and_conquer_part
    pa_truth_shard = self.pmtfy_shard(
  File "/lustre/hpc/icecube/cyan/factory/DOMification/PMTfier.py", line 151, in pmtfy_shard
    summariser  = PMTSummariser(
  File "/lustre/hpc/icecube/cyan/factory/DOMification/PMT_summariser.py", line 71, in __init__
    if PMTSummariser._SCHEMA is None:
AttributeError: type object 'PMTSummariser' has no attribute '_SCHEMA'
"""

The above exception was the direct cause of the following exception:

Traceback (most recent call last):
  File "/lustre/hpc/icecube/cyan/factory/DOMification/PMTfier.py", line 249, in pmtfy_subdir_parallel
    future.result()
  File "/usr/lib64/python3.9/concurrent/futures/_base.py", line 439, in result
    return self.__get_result()
  File "/usr/lib64/python3.9/concurrent/futures/_base.py", line 391, in __get_result
    raise self._exception
AttributeError: type object 'PMTSummariser' has no attribute '_SCHEMA'
2024-11-26 14:13:31 - INFO - Processing shard 1 of part 99 in subdirectory 99999.
2024-11-26 14:13:31 - ERROR - Error processing file merged_part_99.db: type object 'PMTSummariser' has no attribute '_SCHEMA'
concurrent.futures.process._RemoteTraceback: 
"""
Traceback (most recent call last):
  File "/usr/lib64/python3.9/concurrent/futures/process.py", line 246, in _process_worker
    r = call_item.fn(*call_item.args, **call_item.kwargs)
  File "/lustre/hpc/icecube/cyan/factory/DOMification/PMTfier.py", line 205, in pmtfy_part
    consolidated_truth = self._divide_and_conquer_part(
  File "/lustre/hpc/icecube/cyan/factory/DOMification/PMTfier.py", line 183, in _divide_and_conquer_part
    pa_truth_shard = self.pmtfy_shard(
  File "/lustre/hpc/icecube/cyan/factory/DOMification/PMTfier.py", line 151, in pmtfy_shard
    summariser  = PMTSummariser(
  File "/lustre/hpc/icecube/cyan/factory/DOMification/PMT_summariser.py", line 71, in __init__
    if PMTSummariser._SCHEMA is None:
AttributeError: type object 'PMTSummariser' has no attribute '_SCHEMA'
"""

The above exception was the direct cause of the following exception:

Traceback (most recent call last):
  File "/lustre/hpc/icecube/cyan/factory/DOMification/PMTfier.py", line 249, in pmtfy_subdir_parallel
    future.result()
  File "/usr/lib64/python3.9/concurrent/futures/_base.py", line 439, in result
    return self.__get_result()
  File "/usr/lib64/python3.9/concurrent/futures/_base.py", line 391, in __get_result
    raise self._exception
AttributeError: type object 'PMTSummariser' has no attribute '_SCHEMA'
Processing 99999: 100%|██████████| 2/2 [00:00<00:00, 47.93it/s]
2024-11-26 14:13:31 - INFO - PMTfication completed.
