nohup: ignoring input
2024-11-22 10:59:30 - INFO - PMTfication starts...
2024-11-22 10:59:30 - INFO - The number of files in the subdirectory: 2
2024-11-22 10:59:30 - INFO - Using up to 1 workers.
2024-11-22 10:59:30 - INFO - Found 2 database files in subdirectory 99999.
Processing 99999:   0%|          | 0/2 [00:00<?, ?it/s]2024-11-22 10:59:30 - ERROR - Error processing file merged_part_98.db: name 'event_no_subset' is not defined
concurrent.futures.process._RemoteTraceback: 
"""
Traceback (most recent call last):
  File "/usr/lib64/python3.9/concurrent/futures/process.py", line 246, in _process_worker
    r = call_item.fn(*call_item.args, **call_item.kwargs)
  File "/lustre/hpc/icecube/cyan/factory/DOMification/PMTfier.py", line 198, in pmtfy_part
    consolidated_truth = self._divide_and_conquer_part(
  File "/lustre/hpc/icecube/cyan/factory/DOMification/PMTfier.py", line 176, in _divide_and_conquer_part
    pa_truth_shard = self.pmtfy_shard(
  File "/lustre/hpc/icecube/cyan/factory/DOMification/PMTfier.py", line 157, in pmtfy_shard
    veritator = PMTTruthMaker(con_source, source_table, truth_table_name, event_no_subset)
NameError: name 'event_no_subset' is not defined
"""

The above exception was the direct cause of the following exception:

Traceback (most recent call last):
  File "/lustre/hpc/icecube/cyan/factory/DOMification/PMTfier.py", line 246, in pmtfy_subdir_parallel
    future.result()
  File "/usr/lib64/python3.9/concurrent/futures/_base.py", line 439, in result
    return self.__get_result()
  File "/usr/lib64/python3.9/concurrent/futures/_base.py", line 391, in __get_result
    raise self._exception
NameError: name 'event_no_subset' is not defined
Processing 99999:  50%|█████     | 1/2 [00:00<00:00,  2.50it/s]2024-11-22 10:59:32 - ERROR - Error processing file merged_part_99.db: name 'event_no_subset' is not defined
concurrent.futures.process._RemoteTraceback: 
"""
Traceback (most recent call last):
  File "/usr/lib64/python3.9/concurrent/futures/process.py", line 246, in _process_worker
    r = call_item.fn(*call_item.args, **call_item.kwargs)
  File "/lustre/hpc/icecube/cyan/factory/DOMification/PMTfier.py", line 198, in pmtfy_part
    consolidated_truth = self._divide_and_conquer_part(
  File "/lustre/hpc/icecube/cyan/factory/DOMification/PMTfier.py", line 176, in _divide_and_conquer_part
    pa_truth_shard = self.pmtfy_shard(
  File "/lustre/hpc/icecube/cyan/factory/DOMification/PMTfier.py", line 157, in pmtfy_shard
    veritator = PMTTruthMaker(con_source, source_table, truth_table_name, event_no_subset)
NameError: name 'event_no_subset' is not defined
"""

The above exception was the direct cause of the following exception:

Traceback (most recent call last):
  File "/lustre/hpc/icecube/cyan/factory/DOMification/PMTfier.py", line 246, in pmtfy_subdir_parallel
    future.result()
  File "/usr/lib64/python3.9/concurrent/futures/_base.py", line 439, in result
    return self.__get_result()
  File "/usr/lib64/python3.9/concurrent/futures/_base.py", line 391, in __get_result
    raise self._exception
NameError: name 'event_no_subset' is not defined
Processing 99999: 100%|██████████| 2/2 [00:02<00:00,  1.15s/it]Processing 99999: 100%|██████████| 2/2 [00:02<00:00,  1.04s/it]
2024-11-22 10:59:32 - INFO - PMTfication completed.
