nohup: ignoring input
2025-01-16 18:35:20 - INFO - PMTfication for a subdirectory starts...
2025-01-16 18:35:20 - INFO - The number of files in the subdirectory: 2
2025-01-16 18:35:20 - INFO - Using up to 1 workers.
2025-01-16 18:35:20 - INFO - Found 2 database files in subdirectory 99999.
Processing 99999:   0%|          | 0/2 [00:00<?, ?it/s]2025-01-16 18:35:20 - INFO - Processing shard 1 of part 98 in subdirectory 99999.
2025-01-16 18:35:22 - ERROR - Error processing file merged_part_98.db: "The passed mapping doesn't contain the following field(s) of the schema: subdirectory_no, part_no, shard_no, offset"
concurrent.futures.process._RemoteTraceback: 
"""
Traceback (most recent call last):
  File "pyarrow/table.pxi", line 6291, in pyarrow.lib._from_pydict
KeyError: 'subdirectory_no'

During handling of the above exception, another exception occurred:

Traceback (most recent call last):
  File "pyarrow/table.pxi", line 6294, in pyarrow.lib._from_pydict
KeyError: b'subdirectory_no'

During handling of the above exception, another exception occurred:

Traceback (most recent call last):
  File "/usr/lib64/python3.9/concurrent/futures/process.py", line 246, in _process_worker
    r = call_item.fn(*call_item.args, **call_item.kwargs)
  File "/lustre/hpc/icecube/cyan/factory/DOMification/PMTfier.py", line 212, in pmtfy_part
    consolidated_truth = self._divide_and_conquer_part(
  File "/lustre/hpc/icecube/cyan/factory/DOMification/PMTfier.py", line 190, in _divide_and_conquer_part
    pa_truth_shard = self.pmtfy_shard(
  File "/lustre/hpc/icecube/cyan/factory/DOMification/PMTfier.py", line 177, in pmtfy_shard
    pa_truth_shard = truth_maker(int(self.subdir_tag), part_no, shard_no, event_batch)
  File "/lustre/hpc/icecube/cyan/factory/DOMification/PMT_truth_maker.py", line 135, in __call__
    truth_table = self._get_truth_pa_shard(receipt_pa, event_no_subset)
  File "/lustre/hpc/icecube/cyan/factory/DOMification/PMT_truth_maker.py", line 170, in _get_truth_pa_shard
    return self._get_pa_shard(receipt_pa, event_no_subset,
  File "/lustre/hpc/icecube/cyan/factory/DOMification/PMT_truth_maker.py", line 166, in _get_pa_shard
    pa_table = create_table_func(rows, columns)  # Create the table
  File "/lustre/hpc/icecube/cyan/factory/DOMification/PMT_truth_maker.py", line 172, in <lambda>
    lambda rows, cols: self._create_pa_table(rows, cols, PMTTruthMaker._TRUTH_SCHEMA))
  File "/lustre/hpc/icecube/cyan/factory/DOMification/PMT_truth_maker.py", line 234, in _create_pa_table
    table = pa.Table.from_pydict(data, schema=schema)
  File "pyarrow/table.pxi", line 1968, in pyarrow.lib._Tabular.from_pydict
  File "pyarrow/table.pxi", line 6298, in pyarrow.lib._from_pydict
KeyError: "The passed mapping doesn't contain the following field(s) of the schema: subdirectory_no, part_no, shard_no, offset"
"""

The above exception was the direct cause of the following exception:

Traceback (most recent call last):
  File "/lustre/hpc/icecube/cyan/factory/DOMification/PMTfier.py", line 244, in pmtfy_subdir_parallel
    future.result()
  File "/usr/lib64/python3.9/concurrent/futures/_base.py", line 439, in result
    return self.__get_result()
  File "/usr/lib64/python3.9/concurrent/futures/_base.py", line 391, in __get_result
    raise self._exception
KeyError: "The passed mapping doesn't contain the following field(s) of the schema: subdirectory_no, part_no, shard_no, offset"
Processing 99999:  50%|█████     | 1/2 [00:02<00:02,  2.26s/it]2025-01-16 18:35:22 - INFO - Processing shard 1 of part 99 in subdirectory 99999.
2025-01-16 18:35:28 - ERROR - Error processing file merged_part_99.db: "The passed mapping doesn't contain the following field(s) of the schema: subdirectory_no, part_no, shard_no, offset"
concurrent.futures.process._RemoteTraceback: 
"""
Traceback (most recent call last):
  File "pyarrow/table.pxi", line 6291, in pyarrow.lib._from_pydict
KeyError: 'subdirectory_no'

During handling of the above exception, another exception occurred:

Traceback (most recent call last):
  File "pyarrow/table.pxi", line 6294, in pyarrow.lib._from_pydict
KeyError: b'subdirectory_no'

During handling of the above exception, another exception occurred:

Traceback (most recent call last):
  File "/usr/lib64/python3.9/concurrent/futures/process.py", line 246, in _process_worker
    r = call_item.fn(*call_item.args, **call_item.kwargs)
  File "/lustre/hpc/icecube/cyan/factory/DOMification/PMTfier.py", line 212, in pmtfy_part
    consolidated_truth = self._divide_and_conquer_part(
  File "/lustre/hpc/icecube/cyan/factory/DOMification/PMTfier.py", line 190, in _divide_and_conquer_part
    pa_truth_shard = self.pmtfy_shard(
  File "/lustre/hpc/icecube/cyan/factory/DOMification/PMTfier.py", line 177, in pmtfy_shard
    pa_truth_shard = truth_maker(int(self.subdir_tag), part_no, shard_no, event_batch)
  File "/lustre/hpc/icecube/cyan/factory/DOMification/PMT_truth_maker.py", line 135, in __call__
    truth_table = self._get_truth_pa_shard(receipt_pa, event_no_subset)
  File "/lustre/hpc/icecube/cyan/factory/DOMification/PMT_truth_maker.py", line 170, in _get_truth_pa_shard
    return self._get_pa_shard(receipt_pa, event_no_subset,
  File "/lustre/hpc/icecube/cyan/factory/DOMification/PMT_truth_maker.py", line 166, in _get_pa_shard
    pa_table = create_table_func(rows, columns)  # Create the table
  File "/lustre/hpc/icecube/cyan/factory/DOMification/PMT_truth_maker.py", line 172, in <lambda>
    lambda rows, cols: self._create_pa_table(rows, cols, PMTTruthMaker._TRUTH_SCHEMA))
  File "/lustre/hpc/icecube/cyan/factory/DOMification/PMT_truth_maker.py", line 234, in _create_pa_table
    table = pa.Table.from_pydict(data, schema=schema)
  File "pyarrow/table.pxi", line 1968, in pyarrow.lib._Tabular.from_pydict
  File "pyarrow/table.pxi", line 6298, in pyarrow.lib._from_pydict
KeyError: "The passed mapping doesn't contain the following field(s) of the schema: subdirectory_no, part_no, shard_no, offset"
"""

The above exception was the direct cause of the following exception:

Traceback (most recent call last):
  File "/lustre/hpc/icecube/cyan/factory/DOMification/PMTfier.py", line 244, in pmtfy_subdir_parallel
    future.result()
  File "/usr/lib64/python3.9/concurrent/futures/_base.py", line 439, in result
    return self.__get_result()
  File "/usr/lib64/python3.9/concurrent/futures/_base.py", line 391, in __get_result
    raise self._exception
KeyError: "The passed mapping doesn't contain the following field(s) of the schema: subdirectory_no, part_no, shard_no, offset"
Processing 99999: 100%|██████████| 2/2 [00:07<00:00,  4.00s/it]Processing 99999: 100%|██████████| 2/2 [00:07<00:00,  3.74s/it]
2025-01-16 18:35:28 - INFO - PMTfication completed.
