nohup: ignoring input
2025-01-16 17:44:26 - INFO - PMTfication for a subdirectory starts...
2025-01-16 17:44:26 - INFO - The number of files in the subdirectory: 2
2025-01-16 17:44:26 - INFO - Using up to 1 workers.
2025-01-16 17:44:26 - INFO - Found 2 database files in subdirectory 99999.
Processing 99999:   0%|          | 0/2 [00:00<?, ?it/s]2025-01-16 17:44:26 - INFO - Processing shard 1 of part 98 in subdirectory 99999.
2025-01-16 17:44:28 - ERROR - Error processing file merged_part_98.db: Float value 2.2012e+09 was truncated converting to int32
concurrent.futures.process._RemoteTraceback: 
"""
Traceback (most recent call last):
  File "/usr/lib64/python3.9/concurrent/futures/process.py", line 246, in _process_worker
    r = call_item.fn(*call_item.args, **call_item.kwargs)
  File "/lustre/hpc/icecube/cyan/factory/DOMification/PMTfier.py", line 212, in pmtfy_part
    consolidated_truth = self._divide_and_conquer_part(
  File "/lustre/hpc/icecube/cyan/factory/DOMification/PMTfier.py", line 190, in _divide_and_conquer_part
    pa_truth_shard = self.pmtfy_shard(
  File "/lustre/hpc/icecube/cyan/factory/DOMification/PMTfier.py", line 177, in pmtfy_shard
    pa_truth_shard = truth_maker(int(self.subdir_tag), part_no, shard_no, event_batch)
  File "/lustre/hpc/icecube/cyan/factory/DOMification/PMT_truth_maker.py", line 141, in __call__
    return self._merge_tables(truth_table,
  File "/lustre/hpc/icecube/cyan/factory/DOMification/PMT_truth_maker.py", line 364, in _merge_tables
    return pa.Table.from_pydict(merged_data, schema=PMTTruthMaker._MERGED_SCHEMA)
  File "pyarrow/table.pxi", line 1968, in pyarrow.lib._Tabular.from_pydict
  File "pyarrow/table.pxi", line 6303, in pyarrow.lib._from_pydict
  File "pyarrow/array.pxi", line 397, in pyarrow.lib.asarray
  File "pyarrow/table.pxi", line 593, in pyarrow.lib.ChunkedArray.cast
  File "/groups/icecube/cyan/.local/lib/python3.9/site-packages/pyarrow/compute.py", line 405, in cast
    return call_function("cast", [arr], options, memory_pool)
  File "pyarrow/_compute.pyx", line 598, in pyarrow._compute.call_function
  File "pyarrow/_compute.pyx", line 393, in pyarrow._compute.Function.call
  File "pyarrow/error.pxi", line 155, in pyarrow.lib.pyarrow_internal_check_status
  File "pyarrow/error.pxi", line 92, in pyarrow.lib.check_status
pyarrow.lib.ArrowInvalid: Float value 2.2012e+09 was truncated converting to int32
"""

The above exception was the direct cause of the following exception:

Traceback (most recent call last):
  File "/lustre/hpc/icecube/cyan/factory/DOMification/PMTfier.py", line 244, in pmtfy_subdir_parallel
    future.result()
  File "/usr/lib64/python3.9/concurrent/futures/_base.py", line 439, in result
    return self.__get_result()
  File "/usr/lib64/python3.9/concurrent/futures/_base.py", line 391, in __get_result
    raise self._exception
pyarrow.lib.ArrowInvalid: Float value 2.2012e+09 was truncated converting to int32
Processing 99999:  50%|█████     | 1/2 [00:02<00:02,  2.23s/it]2025-01-16 17:44:28 - INFO - Processing shard 1 of part 99 in subdirectory 99999.
2025-01-16 17:44:33 - ERROR - Error processing file merged_part_99.db: Float value 2.2012e+09 was truncated converting to int32
concurrent.futures.process._RemoteTraceback: 
"""
Traceback (most recent call last):
  File "/usr/lib64/python3.9/concurrent/futures/process.py", line 246, in _process_worker
    r = call_item.fn(*call_item.args, **call_item.kwargs)
  File "/lustre/hpc/icecube/cyan/factory/DOMification/PMTfier.py", line 212, in pmtfy_part
    consolidated_truth = self._divide_and_conquer_part(
  File "/lustre/hpc/icecube/cyan/factory/DOMification/PMTfier.py", line 190, in _divide_and_conquer_part
    pa_truth_shard = self.pmtfy_shard(
  File "/lustre/hpc/icecube/cyan/factory/DOMification/PMTfier.py", line 177, in pmtfy_shard
    pa_truth_shard = truth_maker(int(self.subdir_tag), part_no, shard_no, event_batch)
  File "/lustre/hpc/icecube/cyan/factory/DOMification/PMT_truth_maker.py", line 141, in __call__
    return self._merge_tables(truth_table,
  File "/lustre/hpc/icecube/cyan/factory/DOMification/PMT_truth_maker.py", line 364, in _merge_tables
    return pa.Table.from_pydict(merged_data, schema=PMTTruthMaker._MERGED_SCHEMA)
  File "pyarrow/table.pxi", line 1968, in pyarrow.lib._Tabular.from_pydict
  File "pyarrow/table.pxi", line 6303, in pyarrow.lib._from_pydict
  File "pyarrow/array.pxi", line 397, in pyarrow.lib.asarray
  File "pyarrow/table.pxi", line 593, in pyarrow.lib.ChunkedArray.cast
  File "/groups/icecube/cyan/.local/lib/python3.9/site-packages/pyarrow/compute.py", line 405, in cast
    return call_function("cast", [arr], options, memory_pool)
  File "pyarrow/_compute.pyx", line 598, in pyarrow._compute.call_function
  File "pyarrow/_compute.pyx", line 393, in pyarrow._compute.Function.call
  File "pyarrow/error.pxi", line 155, in pyarrow.lib.pyarrow_internal_check_status
  File "pyarrow/error.pxi", line 92, in pyarrow.lib.check_status
pyarrow.lib.ArrowInvalid: Float value 2.2012e+09 was truncated converting to int32
"""

The above exception was the direct cause of the following exception:

Traceback (most recent call last):
  File "/lustre/hpc/icecube/cyan/factory/DOMification/PMTfier.py", line 244, in pmtfy_subdir_parallel
    future.result()
  File "/usr/lib64/python3.9/concurrent/futures/_base.py", line 439, in result
    return self.__get_result()
  File "/usr/lib64/python3.9/concurrent/futures/_base.py", line 391, in __get_result
    raise self._exception
pyarrow.lib.ArrowInvalid: Float value 2.2012e+09 was truncated converting to int32
Processing 99999: 100%|██████████| 2/2 [00:07<00:00,  3.93s/it]Processing 99999: 100%|██████████| 2/2 [00:07<00:00,  3.67s/it]
2025-01-16 17:44:33 - INFO - PMTfication completed.
