nohup: ignoring input
2025-01-16 20:10:22 - INFO - PMTfication for a subdirectory starts...
2025-01-16 20:10:22 - INFO - The number of files in the subdirectory: 2
2025-01-16 20:10:22 - INFO - Using up to 1 workers.
2025-01-16 20:10:22 - INFO - Found 2 database files in subdirectory 99999.
Processing 99999:   0%|          | 0/2 [00:00<?, ?it/s]2025-01-16 20:10:22 - INFO - Processing shard 1 of part 98 in subdirectory 99999.
2025-01-16 20:10:24 - ERROR - Error processing file merged_part_98.db: Cannot append scalar of type int64 to builder for type int32
concurrent.futures.process._RemoteTraceback: 
"""
Traceback (most recent call last):
  File "/usr/lib64/python3.9/concurrent/futures/process.py", line 246, in _process_worker
    r = call_item.fn(*call_item.args, **call_item.kwargs)
  File "/lustre/hpc/icecube/cyan/factory/DOMification/PMTfier.py", line 212, in pmtfy_part
    consolidated_truth = self._divide_and_conquer_part(
  File "/lustre/hpc/icecube/cyan/factory/DOMification/PMTfier.py", line 190, in _divide_and_conquer_part
    pa_truth_shard = self.pmtfy_shard(
  File "/lustre/hpc/icecube/cyan/factory/DOMification/PMTfier.py", line 177, in pmtfy_shard
    pa_truth_shard = truth_maker(int(self.subdir_tag), part_no, shard_no, event_batch)
  File "/lustre/hpc/icecube/cyan/factory/DOMification/PMT_truth_maker.py", line 141, in __call__
    return self._merge_tables(truth_table,
  File "/lustre/hpc/icecube/cyan/factory/DOMification/PMT_truth_maker.py", line 220, in _merge_tables
    merged_data = self._ensure_pyarrow_array(merged_data, PMTTruthMaker._MERGED_SCHEMA)
  File "/lustre/hpc/icecube/cyan/factory/DOMification/PMT_truth_maker.py", line 230, in _ensure_pyarrow_array
    data[field_name] = pa.array(data[field_name], type=field.type)
  File "pyarrow/array.pxi", line 370, in pyarrow.lib.array
  File "pyarrow/array.pxi", line 42, in pyarrow.lib._sequence_to_array
  File "pyarrow/error.pxi", line 155, in pyarrow.lib.pyarrow_internal_check_status
  File "pyarrow/error.pxi", line 92, in pyarrow.lib.check_status
pyarrow.lib.ArrowInvalid: Cannot append scalar of type int64 to builder for type int32
"""

The above exception was the direct cause of the following exception:

Traceback (most recent call last):
  File "/lustre/hpc/icecube/cyan/factory/DOMification/PMTfier.py", line 244, in pmtfy_subdir_parallel
    future.result()
  File "/usr/lib64/python3.9/concurrent/futures/_base.py", line 439, in result
    return self.__get_result()
  File "/usr/lib64/python3.9/concurrent/futures/_base.py", line 391, in __get_result
    raise self._exception
pyarrow.lib.ArrowInvalid: Cannot append scalar of type int64 to builder for type int32
Processing 99999:  50%|█████     | 1/2 [00:02<00:02,  2.33s/it]2025-01-16 20:10:24 - INFO - Processing shard 1 of part 99 in subdirectory 99999.
2025-01-16 20:10:29 - ERROR - Error processing file merged_part_99.db: Cannot append scalar of type int64 to builder for type int32
concurrent.futures.process._RemoteTraceback: 
"""
Traceback (most recent call last):
  File "/usr/lib64/python3.9/concurrent/futures/process.py", line 246, in _process_worker
    r = call_item.fn(*call_item.args, **call_item.kwargs)
  File "/lustre/hpc/icecube/cyan/factory/DOMification/PMTfier.py", line 212, in pmtfy_part
    consolidated_truth = self._divide_and_conquer_part(
  File "/lustre/hpc/icecube/cyan/factory/DOMification/PMTfier.py", line 190, in _divide_and_conquer_part
    pa_truth_shard = self.pmtfy_shard(
  File "/lustre/hpc/icecube/cyan/factory/DOMification/PMTfier.py", line 177, in pmtfy_shard
    pa_truth_shard = truth_maker(int(self.subdir_tag), part_no, shard_no, event_batch)
  File "/lustre/hpc/icecube/cyan/factory/DOMification/PMT_truth_maker.py", line 141, in __call__
    return self._merge_tables(truth_table,
  File "/lustre/hpc/icecube/cyan/factory/DOMification/PMT_truth_maker.py", line 220, in _merge_tables
    merged_data = self._ensure_pyarrow_array(merged_data, PMTTruthMaker._MERGED_SCHEMA)
  File "/lustre/hpc/icecube/cyan/factory/DOMification/PMT_truth_maker.py", line 230, in _ensure_pyarrow_array
    data[field_name] = pa.array(data[field_name], type=field.type)
  File "pyarrow/array.pxi", line 370, in pyarrow.lib.array
  File "pyarrow/array.pxi", line 42, in pyarrow.lib._sequence_to_array
  File "pyarrow/error.pxi", line 155, in pyarrow.lib.pyarrow_internal_check_status
  File "pyarrow/error.pxi", line 92, in pyarrow.lib.check_status
pyarrow.lib.ArrowInvalid: Cannot append scalar of type int64 to builder for type int32
"""

The above exception was the direct cause of the following exception:

Traceback (most recent call last):
  File "/lustre/hpc/icecube/cyan/factory/DOMification/PMTfier.py", line 244, in pmtfy_subdir_parallel
    future.result()
  File "/usr/lib64/python3.9/concurrent/futures/_base.py", line 439, in result
    return self.__get_result()
  File "/usr/lib64/python3.9/concurrent/futures/_base.py", line 391, in __get_result
    raise self._exception
pyarrow.lib.ArrowInvalid: Cannot append scalar of type int64 to builder for type int32
Processing 99999: 100%|██████████| 2/2 [00:07<00:00,  4.12s/it]Processing 99999: 100%|██████████| 2/2 [00:07<00:00,  3.85s/it]
2025-01-16 20:10:29 - INFO - PMTfication completed.
