nohup: ignoring input
2025-02-22 20:30:01 - INFO - PMTfication starts...
2025-02-22 20:30:01 - INFO - The number of files in the subdirectory: 2
2025-02-22 20:30:01 - INFO - The number of files in the subdirectory: 2
2025-02-22 20:30:01 - INFO - Using up to 1 workers.
2025-02-22 20:30:01 - INFO - PMTfying Snowstorm...
2025-02-22 20:30:01 - INFO - Found 2 database files in subdirectory 99999.
Processing 99999:   0%|          | 0/2 [00:00<?, ?it/s]2025-02-22 20:30:01 - INFO - Processing shard 1 of part 98 in subdirectory 99999.
2025-02-22 20:30:09 - ERROR - Error processing file merged_part_98.db: no such column: subdirectory_no
concurrent.futures.process._RemoteTraceback: 
"""
Traceback (most recent call last):
  File "/usr/lib64/python3.9/concurrent/futures/process.py", line 246, in _process_worker
    r = call_item.fn(*call_item.args, **call_item.kwargs)
  File "/lustre/hpc/icecube/cyan/factory/DOMification/PMTfication/PMTfier.py", line 214, in pmtfy_part
    consolidated_truth = self._divide_and_conquer_part(
  File "/lustre/hpc/icecube/cyan/factory/DOMification/PMTfication/PMTfier.py", line 191, in _divide_and_conquer_part
    pa_truth_shard = self.pmtfy_shard(
  File "/lustre/hpc/icecube/cyan/factory/DOMification/PMTfication/PMTfier.py", line 178, in pmtfy_shard
    pa_truth_shard = truth_maker(int(self.subdir_tag), part_no, shard_no, event_batch)
  File "/lustre/hpc/icecube/cyan/factory/DOMification/PMTfication/PMT_truth_maker.py", line 29, in __call__
    truth_table = self._get_truth_pa_shard(receipt_pa, event_no_subset)
  File "/lustre/hpc/icecube/cyan/factory/DOMification/PMTfication/PMT_truth_maker.py", line 91, in _get_truth_pa_shard
    rows, columns = self._execute_query(truth_query)
  File "/lustre/hpc/icecube/cyan/factory/DOMification/PMTfication/PMT_truth_maker.py", line 252, in _execute_query
    cursor.execute(query)
sqlite3.OperationalError: no such column: subdirectory_no
"""

The above exception was the direct cause of the following exception:

Traceback (most recent call last):
  File "/lustre/hpc/icecube/cyan/factory/DOMification/PMTfication/PMTfier.py", line 246, in pmtfy_subdir_parallel
    future.result()
  File "/usr/lib64/python3.9/concurrent/futures/_base.py", line 439, in result
    return self.__get_result()
  File "/usr/lib64/python3.9/concurrent/futures/_base.py", line 391, in __get_result
    raise self._exception
sqlite3.OperationalError: no such column: subdirectory_no
Processing 99999:  50%|█████     | 1/2 [00:08<00:08,  8.06s/it]2025-02-22 20:30:09 - INFO - Processing shard 1 of part 99 in subdirectory 99999.
2025-02-22 20:30:16 - ERROR - Error processing file merged_part_99.db: no such column: subdirectory_no
concurrent.futures.process._RemoteTraceback: 
"""
Traceback (most recent call last):
  File "/usr/lib64/python3.9/concurrent/futures/process.py", line 246, in _process_worker
    r = call_item.fn(*call_item.args, **call_item.kwargs)
  File "/lustre/hpc/icecube/cyan/factory/DOMification/PMTfication/PMTfier.py", line 214, in pmtfy_part
    consolidated_truth = self._divide_and_conquer_part(
  File "/lustre/hpc/icecube/cyan/factory/DOMification/PMTfication/PMTfier.py", line 191, in _divide_and_conquer_part
    pa_truth_shard = self.pmtfy_shard(
  File "/lustre/hpc/icecube/cyan/factory/DOMification/PMTfication/PMTfier.py", line 178, in pmtfy_shard
    pa_truth_shard = truth_maker(int(self.subdir_tag), part_no, shard_no, event_batch)
  File "/lustre/hpc/icecube/cyan/factory/DOMification/PMTfication/PMT_truth_maker.py", line 29, in __call__
    truth_table = self._get_truth_pa_shard(receipt_pa, event_no_subset)
  File "/lustre/hpc/icecube/cyan/factory/DOMification/PMTfication/PMT_truth_maker.py", line 91, in _get_truth_pa_shard
    rows, columns = self._execute_query(truth_query)
  File "/lustre/hpc/icecube/cyan/factory/DOMification/PMTfication/PMT_truth_maker.py", line 252, in _execute_query
    cursor.execute(query)
sqlite3.OperationalError: no such column: subdirectory_no
"""

The above exception was the direct cause of the following exception:

Traceback (most recent call last):
  File "/lustre/hpc/icecube/cyan/factory/DOMification/PMTfication/PMTfier.py", line 246, in pmtfy_subdir_parallel
    future.result()
  File "/usr/lib64/python3.9/concurrent/futures/_base.py", line 439, in result
    return self.__get_result()
  File "/usr/lib64/python3.9/concurrent/futures/_base.py", line 391, in __get_result
    raise self._exception
sqlite3.OperationalError: no such column: subdirectory_no
Processing 99999: 100%|██████████| 2/2 [00:15<00:00,  7.51s/it]Processing 99999: 100%|██████████| 2/2 [00:15<00:00,  7.59s/it]
2025-02-22 20:30:16 - INFO - PMTfication for Snowstorm completed.
2025-02-22 20:30:16 - INFO - PMTfying Corsika...
2025-02-22 20:30:16 - INFO - Found 2 database files in subdirectory 9999999-9999999.
Processing 9999999-9999999:   0%|          | 0/2 [00:00<?, ?it/s]2025-02-22 20:30:16 - INFO - Processing shard 1 of part 96 in subdirectory 9999999-9999999.
2025-02-22 20:30:26 - ERROR - Error processing file merged_part_96.db: no such column: subdirectory_no
concurrent.futures.process._RemoteTraceback: 
"""
Traceback (most recent call last):
  File "/usr/lib64/python3.9/concurrent/futures/process.py", line 246, in _process_worker
    r = call_item.fn(*call_item.args, **call_item.kwargs)
  File "/lustre/hpc/icecube/cyan/factory/DOMification/PMTfication/PMTfier.py", line 214, in pmtfy_part
    consolidated_truth = self._divide_and_conquer_part(
  File "/lustre/hpc/icecube/cyan/factory/DOMification/PMTfication/PMTfier.py", line 191, in _divide_and_conquer_part
    pa_truth_shard = self.pmtfy_shard(
  File "/lustre/hpc/icecube/cyan/factory/DOMification/PMTfication/PMTfier.py", line 178, in pmtfy_shard
    pa_truth_shard = truth_maker(int(self.subdir_tag), part_no, shard_no, event_batch)
  File "/lustre/hpc/icecube/cyan/factory/DOMification/PMTfication/PMT_truth_maker.py", line 29, in __call__
    truth_table = self._get_truth_pa_shard(receipt_pa, event_no_subset)
  File "/lustre/hpc/icecube/cyan/factory/DOMification/PMTfication/PMT_truth_maker.py", line 91, in _get_truth_pa_shard
    rows, columns = self._execute_query(truth_query)
  File "/lustre/hpc/icecube/cyan/factory/DOMification/PMTfication/PMT_truth_maker.py", line 252, in _execute_query
    cursor.execute(query)
sqlite3.OperationalError: no such column: subdirectory_no
"""

The above exception was the direct cause of the following exception:

Traceback (most recent call last):
  File "/lustre/hpc/icecube/cyan/factory/DOMification/PMTfication/PMTfier.py", line 246, in pmtfy_subdir_parallel
    future.result()
  File "/usr/lib64/python3.9/concurrent/futures/_base.py", line 439, in result
    return self.__get_result()
  File "/usr/lib64/python3.9/concurrent/futures/_base.py", line 391, in __get_result
    raise self._exception
sqlite3.OperationalError: no such column: subdirectory_no
Processing 9999999-9999999:  50%|█████     | 1/2 [00:10<00:10, 10.61s/it]2025-02-22 20:30:27 - INFO - Processing shard 1 of part 97 in subdirectory 9999999-9999999.
2025-02-22 20:30:32 - ERROR - Error processing file merged_part_97.db: no such column: subdirectory_no
concurrent.futures.process._RemoteTraceback: 
"""
Traceback (most recent call last):
  File "/usr/lib64/python3.9/concurrent/futures/process.py", line 246, in _process_worker
    r = call_item.fn(*call_item.args, **call_item.kwargs)
  File "/lustre/hpc/icecube/cyan/factory/DOMification/PMTfication/PMTfier.py", line 214, in pmtfy_part
    consolidated_truth = self._divide_and_conquer_part(
  File "/lustre/hpc/icecube/cyan/factory/DOMification/PMTfication/PMTfier.py", line 191, in _divide_and_conquer_part
    pa_truth_shard = self.pmtfy_shard(
  File "/lustre/hpc/icecube/cyan/factory/DOMification/PMTfication/PMTfier.py", line 178, in pmtfy_shard
    pa_truth_shard = truth_maker(int(self.subdir_tag), part_no, shard_no, event_batch)
  File "/lustre/hpc/icecube/cyan/factory/DOMification/PMTfication/PMT_truth_maker.py", line 29, in __call__
    truth_table = self._get_truth_pa_shard(receipt_pa, event_no_subset)
  File "/lustre/hpc/icecube/cyan/factory/DOMification/PMTfication/PMT_truth_maker.py", line 91, in _get_truth_pa_shard
    rows, columns = self._execute_query(truth_query)
  File "/lustre/hpc/icecube/cyan/factory/DOMification/PMTfication/PMT_truth_maker.py", line 252, in _execute_query
    cursor.execute(query)
sqlite3.OperationalError: no such column: subdirectory_no
"""

The above exception was the direct cause of the following exception:

Traceback (most recent call last):
  File "/lustre/hpc/icecube/cyan/factory/DOMification/PMTfication/PMTfier.py", line 246, in pmtfy_subdir_parallel
    future.result()
  File "/usr/lib64/python3.9/concurrent/futures/_base.py", line 439, in result
    return self.__get_result()
  File "/usr/lib64/python3.9/concurrent/futures/_base.py", line 391, in __get_result
    raise self._exception
sqlite3.OperationalError: no such column: subdirectory_no
Processing 9999999-9999999: 100%|██████████| 2/2 [00:16<00:00,  7.57s/it]Processing 9999999-9999999: 100%|██████████| 2/2 [00:16<00:00,  8.03s/it]
2025-02-22 20:30:32 - INFO - PMTfication for Corsika completed.
2025-02-22 20:30:32 - INFO - PMTfication completed.
