nohup: ignoring input
2025-02-22 21:21:00 - INFO - PMTfication starts...
2025-02-22 21:21:00 - INFO - The number of files in the subdirectory: 2
2025-02-22 21:21:00 - INFO - The number of files in the subdirectory: 2
2025-02-22 21:21:00 - INFO - Using up to 1 workers.
2025-02-22 21:21:00 - INFO - PMTfying Snowstorm...
2025-02-22 21:21:00 - INFO - Found 2 database files in subdirectory 99999.
Processing 99999:   0%|          | 0/2 [00:00<?, ?it/s]2025-02-22 21:21:00 - INFO - Processing shard 1 of part 98 in subdirectory 99999.
2025-02-22 21:21:01 - ERROR - Error processing file merged_part_98.db: 'N_doms'
concurrent.futures.process._RemoteTraceback: 
"""
Traceback (most recent call last):
  File "/usr/lib64/python3.9/concurrent/futures/process.py", line 246, in _process_worker
    r = call_item.fn(*call_item.args, **call_item.kwargs)
  File "/lustre/hpc/icecube/cyan/factory/DOMification/PMTfication/PMTfier.py", line 214, in pmtfy_part
    consolidated_truth = self._divide_and_conquer_part(
  File "/lustre/hpc/icecube/cyan/factory/DOMification/PMTfication/PMTfier.py", line 191, in _divide_and_conquer_part
    pa_truth_shard = self.pmtfy_shard(
  File "/lustre/hpc/icecube/cyan/factory/DOMification/PMTfication/PMTfier.py", line 178, in pmtfy_shard
    pa_truth_shard = truth_maker(int(self.subdir_tag), part_no, shard_no, event_batch)
  File "/lustre/hpc/icecube/cyan/factory/DOMification/PMTfication/PMT_truth_maker.py", line 29, in __call__
    truth_table = self._get_truth_pa_shard(receipt_pa, event_no_subset)
  File "/lustre/hpc/icecube/cyan/factory/DOMification/PMTfication/PMT_truth_maker.py", line 92, in _get_truth_pa_shard
    truth_table = self._create_truth_pa_table(rows, columns)
  File "/lustre/hpc/icecube/cyan/factory/DOMification/PMTfication/PMT_truth_maker.py", line 129, in _create_truth_pa_table
    truth_data['offset'] = pc.cumulative_sum(pa.array(truth_data['N_doms']))
KeyError: 'N_doms'
"""

The above exception was the direct cause of the following exception:

Traceback (most recent call last):
  File "/lustre/hpc/icecube/cyan/factory/DOMification/PMTfication/PMTfier.py", line 246, in pmtfy_subdir_parallel
    future.result()
  File "/usr/lib64/python3.9/concurrent/futures/_base.py", line 439, in result
    return self.__get_result()
  File "/usr/lib64/python3.9/concurrent/futures/_base.py", line 391, in __get_result
    raise self._exception
KeyError: 'N_doms'
Processing 99999:  50%|█████     | 1/2 [00:01<00:01,  1.48s/it]2025-02-22 21:21:01 - INFO - Processing shard 1 of part 99 in subdirectory 99999.
2025-02-22 21:21:05 - ERROR - Error processing file merged_part_99.db: 'N_doms'
concurrent.futures.process._RemoteTraceback: 
"""
Traceback (most recent call last):
  File "/usr/lib64/python3.9/concurrent/futures/process.py", line 246, in _process_worker
    r = call_item.fn(*call_item.args, **call_item.kwargs)
  File "/lustre/hpc/icecube/cyan/factory/DOMification/PMTfication/PMTfier.py", line 214, in pmtfy_part
    consolidated_truth = self._divide_and_conquer_part(
  File "/lustre/hpc/icecube/cyan/factory/DOMification/PMTfication/PMTfier.py", line 191, in _divide_and_conquer_part
    pa_truth_shard = self.pmtfy_shard(
  File "/lustre/hpc/icecube/cyan/factory/DOMification/PMTfication/PMTfier.py", line 178, in pmtfy_shard
    pa_truth_shard = truth_maker(int(self.subdir_tag), part_no, shard_no, event_batch)
  File "/lustre/hpc/icecube/cyan/factory/DOMification/PMTfication/PMT_truth_maker.py", line 29, in __call__
    truth_table = self._get_truth_pa_shard(receipt_pa, event_no_subset)
  File "/lustre/hpc/icecube/cyan/factory/DOMification/PMTfication/PMT_truth_maker.py", line 92, in _get_truth_pa_shard
    truth_table = self._create_truth_pa_table(rows, columns)
  File "/lustre/hpc/icecube/cyan/factory/DOMification/PMTfication/PMT_truth_maker.py", line 129, in _create_truth_pa_table
    truth_data['offset'] = pc.cumulative_sum(pa.array(truth_data['N_doms']))
KeyError: 'N_doms'
"""

The above exception was the direct cause of the following exception:

Traceback (most recent call last):
  File "/lustre/hpc/icecube/cyan/factory/DOMification/PMTfication/PMTfier.py", line 246, in pmtfy_subdir_parallel
    future.result()
  File "/usr/lib64/python3.9/concurrent/futures/_base.py", line 439, in result
    return self.__get_result()
  File "/usr/lib64/python3.9/concurrent/futures/_base.py", line 391, in __get_result
    raise self._exception
KeyError: 'N_doms'
Processing 99999: 100%|██████████| 2/2 [00:05<00:00,  2.77s/it]Processing 99999: 100%|██████████| 2/2 [00:05<00:00,  2.57s/it]
2025-02-22 21:21:05 - INFO - PMTfication for Snowstorm completed.
2025-02-22 21:21:05 - INFO - PMTfying Corsika...
2025-02-22 21:21:05 - INFO - Found 2 database files in subdirectory 9999999-9999999.
Processing 9999999-9999999:   0%|          | 0/2 [00:00<?, ?it/s]2025-02-22 21:21:05 - INFO - Processing shard 1 of part 96 in subdirectory 9999999-9999999.
2025-02-22 21:21:07 - ERROR - Error processing file merged_part_96.db: 'N_doms'
concurrent.futures.process._RemoteTraceback: 
"""
Traceback (most recent call last):
  File "/usr/lib64/python3.9/concurrent/futures/process.py", line 246, in _process_worker
    r = call_item.fn(*call_item.args, **call_item.kwargs)
  File "/lustre/hpc/icecube/cyan/factory/DOMification/PMTfication/PMTfier.py", line 214, in pmtfy_part
    consolidated_truth = self._divide_and_conquer_part(
  File "/lustre/hpc/icecube/cyan/factory/DOMification/PMTfication/PMTfier.py", line 191, in _divide_and_conquer_part
    pa_truth_shard = self.pmtfy_shard(
  File "/lustre/hpc/icecube/cyan/factory/DOMification/PMTfication/PMTfier.py", line 178, in pmtfy_shard
    pa_truth_shard = truth_maker(int(self.subdir_tag), part_no, shard_no, event_batch)
  File "/lustre/hpc/icecube/cyan/factory/DOMification/PMTfication/PMT_truth_maker.py", line 29, in __call__
    truth_table = self._get_truth_pa_shard(receipt_pa, event_no_subset)
  File "/lustre/hpc/icecube/cyan/factory/DOMification/PMTfication/PMT_truth_maker.py", line 92, in _get_truth_pa_shard
    truth_table = self._create_truth_pa_table(rows, columns)
  File "/lustre/hpc/icecube/cyan/factory/DOMification/PMTfication/PMT_truth_maker.py", line 129, in _create_truth_pa_table
    truth_data['offset'] = pc.cumulative_sum(pa.array(truth_data['N_doms']))
KeyError: 'N_doms'
"""

The above exception was the direct cause of the following exception:

Traceback (most recent call last):
  File "/lustre/hpc/icecube/cyan/factory/DOMification/PMTfication/PMTfier.py", line 246, in pmtfy_subdir_parallel
    future.result()
  File "/usr/lib64/python3.9/concurrent/futures/_base.py", line 439, in result
    return self.__get_result()
  File "/usr/lib64/python3.9/concurrent/futures/_base.py", line 391, in __get_result
    raise self._exception
KeyError: 'N_doms'
Processing 9999999-9999999:  50%|█████     | 1/2 [00:02<00:02,  2.53s/it]2025-02-22 21:21:07 - INFO - Processing shard 1 of part 97 in subdirectory 9999999-9999999.
2025-02-22 21:21:10 - ERROR - Error processing file merged_part_97.db: 'N_doms'
concurrent.futures.process._RemoteTraceback: 
"""
Traceback (most recent call last):
  File "/usr/lib64/python3.9/concurrent/futures/process.py", line 246, in _process_worker
    r = call_item.fn(*call_item.args, **call_item.kwargs)
  File "/lustre/hpc/icecube/cyan/factory/DOMification/PMTfication/PMTfier.py", line 214, in pmtfy_part
    consolidated_truth = self._divide_and_conquer_part(
  File "/lustre/hpc/icecube/cyan/factory/DOMification/PMTfication/PMTfier.py", line 191, in _divide_and_conquer_part
    pa_truth_shard = self.pmtfy_shard(
  File "/lustre/hpc/icecube/cyan/factory/DOMification/PMTfication/PMTfier.py", line 178, in pmtfy_shard
    pa_truth_shard = truth_maker(int(self.subdir_tag), part_no, shard_no, event_batch)
  File "/lustre/hpc/icecube/cyan/factory/DOMification/PMTfication/PMT_truth_maker.py", line 29, in __call__
    truth_table = self._get_truth_pa_shard(receipt_pa, event_no_subset)
  File "/lustre/hpc/icecube/cyan/factory/DOMification/PMTfication/PMT_truth_maker.py", line 92, in _get_truth_pa_shard
    truth_table = self._create_truth_pa_table(rows, columns)
  File "/lustre/hpc/icecube/cyan/factory/DOMification/PMTfication/PMT_truth_maker.py", line 129, in _create_truth_pa_table
    truth_data['offset'] = pc.cumulative_sum(pa.array(truth_data['N_doms']))
KeyError: 'N_doms'
"""

The above exception was the direct cause of the following exception:

Traceback (most recent call last):
  File "/lustre/hpc/icecube/cyan/factory/DOMification/PMTfication/PMTfier.py", line 246, in pmtfy_subdir_parallel
    future.result()
  File "/usr/lib64/python3.9/concurrent/futures/_base.py", line 439, in result
    return self.__get_result()
  File "/usr/lib64/python3.9/concurrent/futures/_base.py", line 391, in __get_result
    raise self._exception
KeyError: 'N_doms'
Processing 9999999-9999999: 100%|██████████| 2/2 [00:05<00:00,  2.80s/it]Processing 9999999-9999999: 100%|██████████| 2/2 [00:05<00:00,  2.76s/it]
2025-02-22 21:21:10 - INFO - PMTfication for Corsika completed.
2025-02-22 21:21:10 - INFO - PMTfication completed.
