nohup: ignoring input
2025-02-22 21:39:50 - INFO - PMTfication starts...
2025-02-22 21:39:50 - INFO - The number of files in the subdirectory: 2
2025-02-22 21:39:50 - INFO - The number of files in the subdirectory: 2
2025-02-22 21:39:50 - INFO - Using up to 1 workers.
2025-02-22 21:39:50 - INFO - PMTfying Snowstorm...
2025-02-22 21:39:50 - INFO - Found 2 database files in subdirectory 99999.
Processing 99999:   0%|          | 0/2 [00:00<?, ?it/s]2025-02-22 21:39:50 - INFO - Processing shard 1 of part 98 in subdirectory 99999.
2025-02-22 21:39:53 - ERROR - Error processing file merged_part_98.db: 'PMTTruthMaker' object has no attribute '_nan_replacement_HE_DAUGHTER'
concurrent.futures.process._RemoteTraceback: 
"""
Traceback (most recent call last):
  File "/usr/lib64/python3.9/concurrent/futures/process.py", line 246, in _process_worker
    r = call_item.fn(*call_item.args, **call_item.kwargs)
  File "/lustre/hpc/icecube/cyan/factory/DOMification/PMTfication/PMTfier.py", line 214, in pmtfy_part
    consolidated_truth = self._divide_and_conquer_part(
  File "/lustre/hpc/icecube/cyan/factory/DOMification/PMTfication/PMTfier.py", line 191, in _divide_and_conquer_part
    pa_truth_shard = self.pmtfy_shard(
  File "/lustre/hpc/icecube/cyan/factory/DOMification/PMTfication/PMTfier.py", line 178, in pmtfy_shard
    pa_truth_shard = truth_maker(int(self.subdir_tag), part_no, shard_no, event_batch)
  File "/lustre/hpc/icecube/cyan/factory/DOMification/PMTfication/PMT_truth_maker.py", line 55, in __call__
    HE_daughter_table = self._get_pa_shard(
  File "/lustre/hpc/icecube/cyan/factory/DOMification/PMTfication/PMT_truth_maker.py", line 147, in _get_pa_shard
    nan_replacement = getattr(self, f"_nan_replacement_{schema_name}")
AttributeError: 'PMTTruthMaker' object has no attribute '_nan_replacement_HE_DAUGHTER'
"""

The above exception was the direct cause of the following exception:

Traceback (most recent call last):
  File "/lustre/hpc/icecube/cyan/factory/DOMification/PMTfication/PMTfier.py", line 246, in pmtfy_subdir_parallel
    future.result()
  File "/usr/lib64/python3.9/concurrent/futures/_base.py", line 439, in result
    return self.__get_result()
  File "/usr/lib64/python3.9/concurrent/futures/_base.py", line 391, in __get_result
    raise self._exception
AttributeError: 'PMTTruthMaker' object has no attribute '_nan_replacement_HE_DAUGHTER'
Processing 99999:  50%|█████     | 1/2 [00:02<00:02,  2.90s/it]2025-02-22 21:39:53 - INFO - Processing shard 1 of part 99 in subdirectory 99999.
2025-02-22 21:39:59 - ERROR - Error processing file merged_part_99.db: 'PMTTruthMaker' object has no attribute '_nan_replacement_HE_DAUGHTER'
concurrent.futures.process._RemoteTraceback: 
"""
Traceback (most recent call last):
  File "/usr/lib64/python3.9/concurrent/futures/process.py", line 246, in _process_worker
    r = call_item.fn(*call_item.args, **call_item.kwargs)
  File "/lustre/hpc/icecube/cyan/factory/DOMification/PMTfication/PMTfier.py", line 214, in pmtfy_part
    consolidated_truth = self._divide_and_conquer_part(
  File "/lustre/hpc/icecube/cyan/factory/DOMification/PMTfication/PMTfier.py", line 191, in _divide_and_conquer_part
    pa_truth_shard = self.pmtfy_shard(
  File "/lustre/hpc/icecube/cyan/factory/DOMification/PMTfication/PMTfier.py", line 178, in pmtfy_shard
    pa_truth_shard = truth_maker(int(self.subdir_tag), part_no, shard_no, event_batch)
  File "/lustre/hpc/icecube/cyan/factory/DOMification/PMTfication/PMT_truth_maker.py", line 55, in __call__
    HE_daughter_table = self._get_pa_shard(
  File "/lustre/hpc/icecube/cyan/factory/DOMification/PMTfication/PMT_truth_maker.py", line 147, in _get_pa_shard
    nan_replacement = getattr(self, f"_nan_replacement_{schema_name}")
AttributeError: 'PMTTruthMaker' object has no attribute '_nan_replacement_HE_DAUGHTER'
"""

The above exception was the direct cause of the following exception:

Traceback (most recent call last):
  File "/lustre/hpc/icecube/cyan/factory/DOMification/PMTfication/PMTfier.py", line 246, in pmtfy_subdir_parallel
    future.result()
  File "/usr/lib64/python3.9/concurrent/futures/_base.py", line 439, in result
    return self.__get_result()
  File "/usr/lib64/python3.9/concurrent/futures/_base.py", line 391, in __get_result
    raise self._exception
AttributeError: 'PMTTruthMaker' object has no attribute '_nan_replacement_HE_DAUGHTER'
Processing 99999: 100%|██████████| 2/2 [00:08<00:00,  4.33s/it]Processing 99999: 100%|██████████| 2/2 [00:08<00:00,  4.11s/it]
2025-02-22 21:39:59 - INFO - PMTfication for Snowstorm completed.
2025-02-22 21:39:59 - INFO - PMTfying Corsika...
2025-02-22 21:39:59 - INFO - Found 2 database files in subdirectory 9999999-9999999.
Processing 9999999-9999999:   0%|          | 0/2 [00:00<?, ?it/s]2025-02-22 21:39:59 - INFO - Processing shard 1 of part 96 in subdirectory 9999999-9999999.
2025-02-22 21:40:02 - ERROR - Error processing file merged_part_96.db: 'PMTTruthMaker' object has no attribute '_nan_replacement_HE_DAUGHTER'
concurrent.futures.process._RemoteTraceback: 
"""
Traceback (most recent call last):
  File "/usr/lib64/python3.9/concurrent/futures/process.py", line 246, in _process_worker
    r = call_item.fn(*call_item.args, **call_item.kwargs)
  File "/lustre/hpc/icecube/cyan/factory/DOMification/PMTfication/PMTfier.py", line 214, in pmtfy_part
    consolidated_truth = self._divide_and_conquer_part(
  File "/lustre/hpc/icecube/cyan/factory/DOMification/PMTfication/PMTfier.py", line 191, in _divide_and_conquer_part
    pa_truth_shard = self.pmtfy_shard(
  File "/lustre/hpc/icecube/cyan/factory/DOMification/PMTfication/PMTfier.py", line 178, in pmtfy_shard
    pa_truth_shard = truth_maker(int(self.subdir_tag), part_no, shard_no, event_batch)
  File "/lustre/hpc/icecube/cyan/factory/DOMification/PMTfication/PMT_truth_maker.py", line 55, in __call__
    HE_daughter_table = self._get_pa_shard(
  File "/lustre/hpc/icecube/cyan/factory/DOMification/PMTfication/PMT_truth_maker.py", line 147, in _get_pa_shard
    nan_replacement = getattr(self, f"_nan_replacement_{schema_name}")
AttributeError: 'PMTTruthMaker' object has no attribute '_nan_replacement_HE_DAUGHTER'
"""

The above exception was the direct cause of the following exception:

Traceback (most recent call last):
  File "/lustre/hpc/icecube/cyan/factory/DOMification/PMTfication/PMTfier.py", line 246, in pmtfy_subdir_parallel
    future.result()
  File "/usr/lib64/python3.9/concurrent/futures/_base.py", line 439, in result
    return self.__get_result()
  File "/usr/lib64/python3.9/concurrent/futures/_base.py", line 391, in __get_result
    raise self._exception
AttributeError: 'PMTTruthMaker' object has no attribute '_nan_replacement_HE_DAUGHTER'
Processing 9999999-9999999:  50%|█████     | 1/2 [00:03<00:03,  3.33s/it]2025-02-22 21:40:02 - INFO - Processing shard 1 of part 97 in subdirectory 9999999-9999999.
2025-02-22 21:40:05 - ERROR - Error processing file merged_part_97.db: 'PMTTruthMaker' object has no attribute '_nan_replacement_HE_DAUGHTER'
concurrent.futures.process._RemoteTraceback: 
"""
Traceback (most recent call last):
  File "/usr/lib64/python3.9/concurrent/futures/process.py", line 246, in _process_worker
    r = call_item.fn(*call_item.args, **call_item.kwargs)
  File "/lustre/hpc/icecube/cyan/factory/DOMification/PMTfication/PMTfier.py", line 214, in pmtfy_part
    consolidated_truth = self._divide_and_conquer_part(
  File "/lustre/hpc/icecube/cyan/factory/DOMification/PMTfication/PMTfier.py", line 191, in _divide_and_conquer_part
    pa_truth_shard = self.pmtfy_shard(
  File "/lustre/hpc/icecube/cyan/factory/DOMification/PMTfication/PMTfier.py", line 178, in pmtfy_shard
    pa_truth_shard = truth_maker(int(self.subdir_tag), part_no, shard_no, event_batch)
  File "/lustre/hpc/icecube/cyan/factory/DOMification/PMTfication/PMT_truth_maker.py", line 55, in __call__
    HE_daughter_table = self._get_pa_shard(
  File "/lustre/hpc/icecube/cyan/factory/DOMification/PMTfication/PMT_truth_maker.py", line 147, in _get_pa_shard
    nan_replacement = getattr(self, f"_nan_replacement_{schema_name}")
AttributeError: 'PMTTruthMaker' object has no attribute '_nan_replacement_HE_DAUGHTER'
"""

The above exception was the direct cause of the following exception:

Traceback (most recent call last):
  File "/lustre/hpc/icecube/cyan/factory/DOMification/PMTfication/PMTfier.py", line 246, in pmtfy_subdir_parallel
    future.result()
  File "/usr/lib64/python3.9/concurrent/futures/_base.py", line 439, in result
    return self.__get_result()
  File "/usr/lib64/python3.9/concurrent/futures/_base.py", line 391, in __get_result
    raise self._exception
AttributeError: 'PMTTruthMaker' object has no attribute '_nan_replacement_HE_DAUGHTER'
Processing 9999999-9999999: 100%|██████████| 2/2 [00:06<00:00,  3.42s/it]Processing 9999999-9999999: 100%|██████████| 2/2 [00:06<00:00,  3.41s/it]
2025-02-22 21:40:05 - INFO - PMTfication for Corsika completed.
2025-02-22 21:40:05 - INFO - PMTfication completed.
